2018-08-09 14:51:03,705 - loggingmodule.py - 22156 - MainProcess - MainThread - DEBUG - Start of program
2018-08-09 14:51:03,705 - loggingmodule.py - 22156 - MainProcess - MainThread - DEBUG - Start of factorial(5)
2018-08-09 14:51:03,705 - loggingmodule.py - 22156 - MainProcess - MainThread - DEBUG - i is 1, total is 1
2018-08-09 14:51:03,706 - loggingmodule.py - 22156 - MainProcess - MainThread - DEBUG - i is 2, total is 2
2018-08-09 14:51:03,706 - loggingmodule.py - 22156 - MainProcess - MainThread - DEBUG - i is 3, total is 6
2018-08-09 14:51:03,706 - loggingmodule.py - 22156 - MainProcess - MainThread - DEBUG - i is 4, total is 24
2018-08-09 14:51:03,706 - loggingmodule.py - 22156 - MainProcess - MainThread - DEBUG - i is 5, total is 120
2018-08-09 14:51:03,706 - loggingmodule.py - 22156 - MainProcess - MainThread - DEBUG - End of factorial(5)
2018-08-09 14:51:03,712 - loggingmodule.py - 22156 - MainProcess - MainThread - DEBUG - End of program
2018-08-09 14:51:03,717 - loggingmodule.py - 22156 - MainProcess - MainThread - WARNING - An error msg is about to be logged
2018-08-09 14:51:03,717 - loggingmodule.py - 22156 - MainProcess - MainThread - ERROR - An error has occurred
2018-08-09 14:51:03,717 - loggingmodule.py - 22156 - MainProcess - MainThread - CRITICAL - Program unable to recover
